2025-10-11 14:35:04,298 - INFO - [31m[1mWARNING: This is a development server. Do not use it in a production deployment. Use a production WSGI server instead.[0m
 * Running on all addresses (0.0.0.0)
 * Running on http://127.0.0.1:5000
 * Running on http://192.168.0.193:5000
2025-10-11 14:35:04,299 - INFO - [33mPress CTRL+C to quit[0m
2025-10-11 14:35:04,299 - INFO -  * Restarting with stat
2025-10-11 14:35:05,215 - WARNING -  * Debugger is active!
2025-10-11 14:35:05,215 - INFO -  * Debugger PIN: 122-812-795
2025-10-11 14:35:51,253 - ERROR - Exception on / [GET]
Traceback (most recent call last):
  File "/home/bren/Home/Projects/HTML_CSS/precinct/.venv/lib/python3.11/site-packages/flask/app.py", line 1511, in wsgi_app
    response = self.full_dispatch_request()
               ^^^^^^^^^^^^^^^^^^^^^^^^^^^^
  File "/home/bren/Home/Projects/HTML_CSS/precinct/.venv/lib/python3.11/site-packages/flask/app.py", line 919, in full_dispatch_request
    rv = self.handle_user_exception(e)
         ^^^^^^^^^^^^^^^^^^^^^^^^^^^^^
  File "/home/bren/Home/Projects/HTML_CSS/precinct/.venv/lib/python3.11/site-packages/flask/app.py", line 915, in full_dispatch_request
    rv = self.preprocess_request()
         ^^^^^^^^^^^^^^^^^^^^^^^^^
  File "/home/bren/Home/Projects/HTML_CSS/precinct/.venv/lib/python3.11/site-packages/flask/app.py", line 1291, in preprocess_request
    rv = self.ensure_sync(before_func)()
         ^^^^^^^^^^^^^^^^^^^^^^^^^^^^^^^
  File "/home/bren/Home/Projects/HTML_CSS/precinct/main.py", line 111, in security_middleware
    session['last_activity'] = datetime.now().isoformat()
                               ^^^^^^^^
UnboundLocalError: cannot access local variable 'datetime' where it is not associated with a value
2025-10-11 14:35:51,254 - ERROR - Internal server error: 500 Internal Server Error: The server encountered an internal error and was unable to complete your request. Either the server is overloaded or there is an error in the application.
2025-10-11 14:35:56,983 - ERROR - Exception on / [GET]
Traceback (most recent call last):
  File "/home/bren/Home/Projects/HTML_CSS/precinct/.venv/lib/python3.11/site-packages/flask/app.py", line 1511, in wsgi_app
    response = self.full_dispatch_request()
               ^^^^^^^^^^^^^^^^^^^^^^^^^^^^
  File "/home/bren/Home/Projects/HTML_CSS/precinct/.venv/lib/python3.11/site-packages/flask/app.py", line 919, in full_dispatch_request
    rv = self.handle_user_exception(e)
         ^^^^^^^^^^^^^^^^^^^^^^^^^^^^^
  File "/home/bren/Home/Projects/HTML_CSS/precinct/.venv/lib/python3.11/site-packages/flask/app.py", line 915, in full_dispatch_request
    rv = self.preprocess_request()
         ^^^^^^^^^^^^^^^^^^^^^^^^^
  File "/home/bren/Home/Projects/HTML_CSS/precinct/.venv/lib/python3.11/site-packages/flask/app.py", line 1291, in preprocess_request
    rv = self.ensure_sync(before_func)()
         ^^^^^^^^^^^^^^^^^^^^^^^^^^^^^^^
  File "/home/bren/Home/Projects/HTML_CSS/precinct/main.py", line 111, in security_middleware
    session['last_activity'] = datetime.now().isoformat()
                               ^^^^^^^^
UnboundLocalError: cannot access local variable 'datetime' where it is not associated with a value
2025-10-11 14:35:56,984 - ERROR - Internal server error: 500 Internal Server Error: The server encountered an internal error and was unable to complete your request. Either the server is overloaded or there is an error in the application.
